<?xml version="1.0"?>
<robot name="dodobot" xmlns:xacro="http://www.ros.org/wiki/xacro">
  <material name="orange">
    <color rgba="0.8 0.4 0.0 1.0"/>
  </material>

  <material name="black">
    <color rgba="0.2 0.2 0.2 1.0"/>
  </material>

  <material name="gray">
    <color rgba="0.5 0.5 0.5 1.0"/>
  </material>

  <!-- Base Link -->
  <link name="base_footprint">
    <inertial>
      <origin xyz="0 0 0.005" rpy="0 0 0"/>
      <mass value="5"/>
      <inertia ixx="0.0395" ixy="0" ixz="0" iyy="0.106" iyz="0" izz="0.145"/>
    </inertial>
    <visual>
      <origin xyz="0 0 0.005" rpy="0 0 0"/>
      <geometry>
        <box size="0.6 0.3 0.01"/>
      </geometry>
      <material name="gray"/>
    </visual>
    <collision>
      <origin xyz="0 0 0.005" rpy="0 0 0"/>
      <geometry>
        <box size="0.6 0.3 0.01"/>
      </geometry>
    </collision>
  </link>

  <!-- Compartment 1 -->
  <link name="compartment_1">
    <inertial>
      <origin xyz="0 0 0" rpy="0 0 0"/>
      <mass value="2"/>
      <inertia ixx="0.0275" ixy="0" ixz="0" iyy="0.0275" iyz="0" izz="0.015"/>
    </inertial>
    <visual>
      <origin xyz="0 0 0" rpy="0 0 0"/>
      <geometry>
        <box size="0.4 0.30 0.30"/>
      </geometry>
      <material name="black"/>
    </visual>
    <collision>
      <origin xyz="0 0 0" rpy="0 0 0"/>
      <geometry>
        <box size="0.4 0.30 0.30"/>
      </geometry>
    </collision>
  </link>

  <joint name="base_to_compartment_1" type="fixed">
    <parent link="base_footprint"/>
    <child link="compartment_1"/>
    <origin xyz="0.10 0 0.155" rpy="0 0 0"/>
  </joint>

  <!-- Compartment 2 -->
  <link name="compartment_2">
    <inertial>
      <origin xyz="0 0 0" rpy="0 0 0"/>
      <mass value="1"/>
      <inertia ixx="0.0108" ixy="0" ixz="0" iyy="0.0083" iyz="0" izz="0.0058"/>
    </inertial>
    <visual>
      <origin xyz="0 0 0" rpy="0 0 0"/>
      <geometry>
        <box size="0.20 0.30 0.30"/>
      </geometry>
      <material name="orange"/>
    </visual>
    <collision>
      <origin xyz="0 0 0" rpy="0 0 0"/>
      <geometry>
        <box size="0.20 0.30 0.30"/>
      </geometry>
    </collision>
  </link>

  <joint name="base_to_compartment_2" type="fixed">
    <parent link="base_footprint"/>
    <child link="compartment_2"/>
    <origin xyz="-0.20 0 0.155" rpy="0 0 0"/>
  </joint>

  <!-- Compartment 3 -->
  <link name="compartment_3">
    <inertial>
      <origin xyz="0 0 0" rpy="0 0 0"/>
      <mass value="1.5"/>
      <inertia ixx="0.0234375" ixy="0" ixz="0" iyy="0.0234375" iyz="0" izz="0.015625"/>
    </inertial>
    <visual>
      <origin xyz="0 0 0" rpy="0 0 0"/>
      <geometry>
        <box size="0.25 0.25 0.30"/>
      </geometry>
      <material name="black"/>
    </visual>
    <collision>
      <origin xyz="0 0 0" rpy="0 0 0"/>
      <geometry>
        <box size="0.25 0.25 0.30"/>
      </geometry>
    </collision>
  </link>

  <joint name="compartment_1_to_compartment_3" type="fixed">
    <parent link="compartment_1"/>
    <child link="compartment_3"/>
    <origin xyz="0 0 0.30" rpy="0 0 0"/>
  </joint>

  <!-- Left Compartment 1 Wheel -->
  <link name="left_compartment_1_wheel">
    <inertial>
      <origin xyz="0 0 0" rpy="0 0 0"/>
      <mass value="0.5"/>
      <inertia ixx="0.000703" ixy="0" ixz="0" iyy="0.000703" iyz="0" izz="0.001406"/>
    </inertial>
    <visual>
      <origin xyz="0 0 0" rpy="1.5708 0 0"/>
      <geometry>
        <cylinder radius="0.10" length="0.015"/>
      </geometry>
      <material name="gray"/>
    </visual>
    <collision>
      <origin xyz="0 0 0" rpy="1.5708 0 0"/>
      <geometry>
        <cylinder radius="0.10" length="0.015"/>
      </geometry>
    </collision>
  </link>

  <joint name="base_to_left_compartment_1_wheel" type="continuous">
    <parent link="base_footprint"/>
    <child link="left_compartment_1_wheel"/>
    <origin xyz="0.20 0.1575 0" rpy="0 0 0"/>
    <axis xyz="0 1 0"/>
  </joint>

  <!-- Right Compartment 1 Wheel -->
  <link name="right_compartment_1_wheel">
    <inertial>
      <origin xyz="0 0 0" rpy="0 0 0"/>
      <mass value="0.5"/>
      <inertia ixx="0.000703" ixy="0" ixz="0" iyy="0.000703" iyz="0" izz="0.001406"/>
    </inertial>
    <visual>
      <origin xyz="0 0 0" rpy="1.5708 0 0"/>
      <geometry>
        <cylinder radius="0.10" length="0.015"/>
      </geometry>
      <material name="gray"/>
    </visual>
    <collision>
      <origin xyz="0 0 0" rpy="1.5708 0 0"/>
      <geometry>
        <cylinder radius="0.10" length="0.015"/>
      </geometry>
    </collision>
  </link>

  <joint name="base_to_right_compartment_1_wheel" type="continuous">
    <parent link="base_footprint"/>
    <child link="right_compartment_1_wheel"/>
    <origin xyz="0.20 -0.1575 0" rpy="0 0 0"/>
    <axis xyz="0 1 0"/>
  </joint>

  <!-- Left Compartment 2 Wheel (Caster) -->
  <link name="left_compartment_2_wheel">
    <inertial>
      <origin xyz="0 0 0" rpy="0 0 0"/>
      <mass value="0.05"/>
      <inertia ixx="0.0000281" ixy="0" ixz="0" iyy="0.0000281" iyz="0" izz="0.0000281"/>
    </inertial>
    <visual>
      <origin xyz="0 0 0" rpy="0 0 0"/>
      <geometry>
        <sphere radius="0.0375"/>
      </geometry>
      <material name="gray"/>
    </visual>
    <collision>
      <origin xyz="0 0 0" rpy="0 0 0"/>
      <geometry>
        <sphere radius="0.0375"/>
      </geometry>
    </collision>
  </link>

  <joint name="base_to_left_compartment_2_wheel" type="fixed">
    <parent link="base_footprint"/>
    <child link="left_compartment_2_wheel"/>
    <origin xyz="-0.20 0.14 -0.0375" rpy="0 0 0"/>
  </joint>

  <!-- Right Compartment 2 Wheel (Caster) -->
  <link name="right_compartment_2_wheel">
    <inertial>
      <origin xyz="0 0 0" rpy="0 0 0"/>
      <mass value="0.05"/>
      <inertia ixx="0.0000281" ixy="0" ixz="0" iyy="0.0000281" iyz="0" izz="0.0000281"/>
    </inertial>
    <visual>
      <origin xyz="0 0 0" rpy="0 0 0"/>
      <geometry>
        <sphere radius="0.0375"/>
      </geometry>
      <material name="gray"/>
    </visual>
    <collision>
      <origin xyz="0 0 0" rpy="0 0 0"/>
      <geometry>
        <sphere radius="0.0375"/>
      </geometry>
    </collision>
  </link>


  <joint name="base_to_right_compartment_2_wheel" type="fixed">
    <parent link="base_footprint"/>
    <child link="right_compartment_2_wheel"/>
    <origin xyz="-0.20 -0.14 -0.0375" rpy="0 0 0"/>
  </joint>

  <!-- LiDAR -->
  <link name="lidar_link">
    <inertial>
      <mass value="0.1"/>
      <inertia ixx="0.000166667" iyy="0.000166667" izz="0.000166667" ixy="0" ixz="0" iyz="0"/>
    </inertial>
    <collision>
      <geometry>
        <cylinder radius="0.05" length="0.1"/>
      </geometry>
    </collision>
    <visual>
      <geometry>
        <cylinder radius="0.05" length="0.1"/>
      </geometry>
      <material name="gray"/>
    </visual>
  </link>

  <joint name="compartment_3_to_lidar" type="fixed">
    <parent link="compartment_3"/>
    <child link="lidar_link"/>
    <origin xyz="0 0 0.20" rpy="0 0 0"/>
  </joint>


  <!-- Wide Angle Camera -->
  <link name="wide_angle_camera_link">
    <inertial>
      <mass value="0.1"/>
      <inertia ixx="0.000166667" iyy="0.000166667" izz="0.000166667" ixy="0" ixz="0" iyz="0"/>
    </inertial>
    <visual>
      <geometry>
        <box size="0.1 0.1 0.1"/>
      </geometry>
      <material name="gray"/>
    </visual>
    <collision>
      <geometry>
        <box size="0.1 0.1 0.1"/>
      </geometry>
    </collision>
  </link>

  <joint name="compartment_1_to_camera" type="fixed">
    <parent link="compartment_1"/>
    <child link="wide_angle_camera_link"/>
    <origin xyz="0.20 0 0.15" rpy="0 0 0"/>
  </joint>


  <!-- Rear Wide Angle Camera -->
  <link name="rear_wide_angle_camera_link">
    <inertial>
      <mass value="0.1"/>
      <inertia ixx="0.000166667" iyy="0.000166667" izz="0.000166667" ixy="0" ixz="0" iyz="0"/>
    </inertial>
    <visual>
      <geometry>
        <box size="0.1 0.1 0.1"/>
      </geometry>
      <material name="gray"/>
    </visual>
    <collision>
      <geometry>
        <box size="0.1 0.1 0.1"/>
      </geometry>
    </collision>
  </link>

  <joint name="compartment_2_to_rear_camera" type="fixed">
    <parent link="compartment_2"/>
    <child link="rear_wide_angle_camera_link"/>
    <origin xyz="-0.10 0 0.15" rpy="0 0 3.14159"/>
  </joint>

</robot>

